Workbook

Sheet Datos Estudiantes
A1: Horas de consumo de redes sociales por día | B1: Rendimiento académico
A2: 2 | B2: 9 | D2: x => | E2: =MIN(A2:A201) -> 1
A3: 4 | B3: 8 | E3: =MAX(A2:A201) -> 8
A4: 3 | B4: 8
A5: 2 | B5: 8 | E5: =COUNTIF(A2:A201,1) -> 24
A6: 7 | B6: 7 | E6: =COUNTIF(A2:A201,2) -> 27
A7: 4 | B7: 8 | E7: =COUNTIF(A2:A201,3) -> 28
A8: 1 | B8: 8 | E8: =COUNTIF(A2:A201,4) -> 32
A9: 7 | B9: 6 | E9: =COUNTIF(A2:A201,5) -> 26
A10: 4 | B10: 7 | E10: =COUNTIF(A2:A201,6) -> 26
A11: 1 | B11: 9 | E11: =COUNTIF(A2:A201,7) -> 24
A12: 3 | B12: 8 | E12: =COUNTIF(A2:A201,8) -> 13
A13: 3 | B13: 8 | E13: =COUNTIF(A2:A201,9) -> 0
A14: 4 | B14: 9
A15: 2 | B15: 9
A16: 7 | B16: 8
A17: 5 | B17: 8
A18: 1 | B18: 9
A19: 7 | B19: 6
A20: 2 | B20: 7
A21: 6 | B21: 7
A22: 4 | B22: 8
A23: 4 | B23: 8
A24: 5 | B24: 9
A25: 2 | B25: 9
... A201: 1 | B201: 9

Sheet Resoluciones
A1: LA CEBOLLA
A4: a) Identificar: | N4: f) Calcular e interpretar
A5: Horas de consumo de redes sociales por día | G5: Rendimiento académico | N5: Media Aritmetica | P5: Moda | R5: Mediana | T5: Coeficiente de Asimetria | V5: Coeficiente de Curtosis
A6: Variable estadística. | C6: Tipo de variable. | E6: Escala de medición. | G6: Variable estadística. | I6: Tipo de variable. | K6: Escala de medición.
A7: Cuantitativa | C7: Discreta | E7: De Razon | G7: Cuantitativa | I7: Discreta | K7: Intervalo | N7: =AVERAGE(B17:B24) -> 25 | P7: =B20 -> 32 | R7: =B25/2 -> 100 | T7: =J25/(B25*Q12^3) -> -1.0151907 | V7: =K25/(B25*Q12^4) -> 0.11658881
A10: b) Identificar: | N10: g) Calcular e interpretar
A11: Poblacion | E11: Muestra | I11: Unidad de observacion | N11: Varianza | Q11: Desvio Estandar | T11: Coeficiente de Variacion
A12: Jovenes de la provincia de Formosa | E12: Los 200 estudiantes seleccionados para el estudio | I12: Cada estudiante que ha completado el cuestionario | N12: =I25/B25 -> 435.45 | Q12: =SQRT(N12) -> 20.867439 | T12: =Q12/B25*100 -> 10.433719
A15: c) Tabla de Frecuencias | N15: h) Calcular e interpretar
A16: x | B16: fi | C16: Fi | D16: fri | E16: Fri | F16: pi% | G16: Pi% | H16: x*f | I16: (x-prom)^2*fi | J16: (x-prom)^3*fi | K16: (x-prom)^4*fi | N16: Cuartiles | Q16: Deciles | T16: Percentiles
A17: 1 | B17: 24 | C17: =B17 -> 24 | D17: =B17/$B$25 -> 0.12 | E17: =D17 -> 0.12 | F17: =D17*100 -> 12 | G17: =E17*100 -> 12 | H17: =A17*B17 -> 24 | I17: =(A17-$N$7)^2*B17 -> 13824 | J17: =(A17-$N$7)^3*B17 -> -331776 | K17: =(B17-$N$7)^4*C17 -> 24 | N17: Q1 | O17: 2 | Q17: D3 | R17: 3 | T17: P23 | U17: 2
A18: 2 | B18: 27 | C18: =C17+B18 -> 51 | D18: =B18/$B$25 -> 0.135 | E18: =E17+D18 -> 0.255 | F18: =D18*100 -> 13.5 | G18: =E18*100 -> 25.5 | H18: =A18*B18 -> 54 | I18: =(A18-$N$7)^2*B18 -> 14283 | J18: =(A18-$N$7)^3*B18 -> -328509 | K18: =(B18-$N$7)^4*C18 -> 816 | N18: Q3 | O18: 6 | Q18: D4 | R18: 4 | T18: P75 | U18: 6
A19: 3 | B19: 28 | C19: =C18+B19 -> 79 | D19: =B19/$B$25 -> 0.14 | E19: =E18+D19 -> 0.395 | F19: =D19*100 -> 14 | G19: =E19*100 -> 39.5 | H19: =A19*B19 -> 84 | I19: =(A19-$N$7)^2*B19 -> 13552 | J19: =(A19-$N$7)^3*B19 -> -298144 | K19: =(B19-$N$7)^4*C19 -> 6399 | Q19: D9 | R19: 7 | T19: P97 | U19: 8
A20: 4 | B20: 32 | C20: =C19+B20 -> 111 | D20: =B20/$B$25 -> 0.16 | E20: =E19+D20 -> 0.555 | F20: =D20*100 -> 16 | G20: =E20*100 -> 55.5 | H20: =A20*B20 -> 128 | I20: =(A20-$N$7)^2*B20 -> 14112 | J20: =(A20-$N$7)^3*B20 -> -296352 | K20: =(B20-$N$7)^4*C20 -> 266511 | N20: indicador | O20: =1*B25/4 -> 50
A21: 5 | B21: 26 | C21: =C20+B21 -> 137 | D21: =B21/$B$25 -> 0.13 | E21: =E20+D21 -> 0.685 | F21: =D21*100 -> 13 | G21: =E21*100 -> 68.5 | H21: =A21*B21 -> 130 | I21: =(A21-$N$7)^2*B21 -> 10400 | J21: =(A21-$N$7)^3*B21 -> -208000 | K21: =(B21-$N$7)^4*C21 -> 137 | O21: =3*B25/4 -> 150 | Q21: indicador | R21: =3*B25/10 -> 60 | T21: indicador | U21: =23*B25/100 -> 46
A22: 6 | B22: 26 | C22: =C21+B22 -> 163 | D22: =B22/$B$25 -> 0.13 | E22: =E21+D22 -> 0.815 | F22: =D22*100 -> 13 | G22: =E22*100 -> 81.5 | H22: =A22*B22 -> 156 | I22: =(A22-$N$7)^2*B22 -> 9386 | J22: =(A22-$N$7)^3*B22 -> -178334 | K22: =(B22-$N$7)^4*C22 -> 163 | R22: =4*B25/10 -> 80 | U22: =75*B25/100 -> 150
A23: 7 | B23: 24 | C23: =C22+B23 -> 187 | D23: =B23/$B$25 -> 0.12 | E23: =E22+D23 -> 0.935 | F23: =D23*100 -> 12 | G23: =E23*100 -> 93.5 | H23: =A23*B23 -> 168 | I23: =(A23-$N$7)^2*B23 -> 7776 | J23: =(A23-$N$7)^3*B23 -> -139968 | K23: =(B23-$N$7)^4*C23 -> 187 | R23: =9*B25/10 -> 180 | U23: =97*B25/100 -> 194
A24: 8 | B24: 13 | C24: =C23+B24 -> 200 | D24: =B24/$B$25 -> 0.065 | E24: =E23+D24 -> 1 | F24: =D24*100 -> 6.5 | G24: =E24*100 -> 100 | H24: =A24*B24 -> 104 | I24: =(A24-$N$7)^2*B24 -> 3757 | J24: =(A24-$N$7)^3*B24 -> -63869 | K24: =(B24-$N$7)^4*C24 -> 4147200
B25: =SUM(B17:B24) -> 200 | I25: =SUM(I17:I24) -> 87090 | J25: =SUM(J17:J24) -> -1844952 | K25: =SUM(K17:K24) -> 4421437
D27: Interpretaciones
A28: fi2 | B28: 27 jovenes utilizan el celular exactamente 2 horas al dia | F28: fi5 | G28: 26 jovenes utilizan el celular exactamente 5 horas al dia
A30: fi8 | B30: 13 jovenes utilizan el celular exactamente 8 horas al dia | F30: Fi4 | G30: 111 jovenes utilizan el celular hasta 4 horas al dia
A32: Fi7 | B32: 187 jovenes utilizan el celular hasta 7 horas al dia | F32: pi3 | G32: 14% de los jovenes utilizan el celular exactamente 3 horas al dia
A34: pi6 | B34: 13% de los jovenes utilizan el celular exactamente 6 horas al dia | F34: pi8 | G34: 6,5% de los jovenes utilizan el celular exactamente 8 horas al dia
D36: Pi8 | E36: 100% de los jovenes utilizan el celular hasta 8 horas al dia
A39: e) Determinar
A40: Cantidad de estudiantes que utilizan entre 3 y 8 horas diarias las redes sociales.
E41: La cantidad de jovenes que utilizan entre 3 y 8 horas diaras las redes sociales es de 149
A45: Porcentaje de estudiantes que utilizan más de 6 horas diarias las redes sociales.
E46: El porcentaje de jovenes que utilizan mas de 6 horas diarias las redes sociales es del 18,5%
A50: Cantidad de estudiantes que utilizan menos de 2 horas diarias las redes sociales.
E51: La cantidad de jovenes que utilizan menos de 2 horas diarias las redes sociales es de 24
A55: Porcentaje de estudiantes que utilizan entre 5 y 8 horas diarias las redes sociales.
E56: La cantidad de jovenes que utilizan entre 5 y 8 horas diarias las redes sociales es del 44,5% | I56: =SUM(F21:F24) -> 44.5
A60: Cantidad de estudiantes que utilizan más de 8 horas diarias las redes sociales.
E61: La cantidad de jovenes que utilizan mas de 8 horas diarias las redes sociales es de 0
A65: Porcentaje de estudiantes que utilizan menos de 4 horas diarias las redes sociales.
E66: El porcentaje de jovenes que utilizan menos de 4 horas diarias las redes sociales es del 39,5%
A70: Cantidad de estudiantes que utilizan entre 1 y 6 horas diarias las redes sociales.
E71: La cantidad de estudiantes que utilizan entre 1 y 6 horas diarias las redes sociales es de 163
...

Sheet Etapa 5
A1: ETAPA 5: CORRELACIÓN Y REGRESIÓN LINEAL
A2: Variables: X = Horas de redes sociales por día | Y = Rendimiento académico
A4: Cálculos
A5: n (cantidad de estudiantes) | B5: =COUNT('Datos Estudiantes'!$A$2:$A$201) -> 200
A6: Media de X (horas) | B6: =AVERAGE('Datos Estudiantes'!$A$2:$A$201) -> 4.24
A7: Media de Y (rendimiento) | B7: =AVERAGE('Datos Estudiantes'!$B$2:$B$201) -> 7.79
A8: Pendiente (b) | B8: =SLOPE('Datos Estudiantes'!$B$2:$B$201,'Datos Estudiantes'!$A$2:$A$201) -> -0.37890171
A9: Ordenada al origen (a) | B9: =INTERCEPT('Datos Estudiantes'!$B$2:$B$201,'Datos Estudiantes'!$A$2:$A$201) -> 9.3965432
A10: Coef. de correlación (r) | B10: =CORREL('Datos Estudiantes'!$A$2:$A$201,'Datos Estudiantes'!$B$2:$B$201) -> -0.68562624
A11: Coef. de determinación (r²) | B11: =RSQ('Datos Estudiantes'!$B$2:$B$201,'Datos Estudiantes'!$A$2:$A$201) -> 0.47008334
A13: Recta de regresión | B13: ="ŷ = "&ROUND(B9,3)&" "&TEXT(B8,"+0.000;-0.000")&"·x" -> ŷ = 9.397 -0.379·x
A15: Interpretaciones
A16: b) Tipo de correlación: | B16: Se observa una correlación lineal NEGATIVA de intensidad moderada-fuerte: a medida que aumentan las horas de redes sociales, el rendimiento académico tiende a disminuir.
A17: c) Recta de regresión: | B17: ŷ = 9,397 − 0,379·x. Se obtuvo con las funciones PENDIENTE e INTERSECCION.EJE de Excel.
A18: d) Pendiente: | B18: b = −0,379: por cada hora adicional de redes sociales por día, el rendimiento académico disminuye en promedio 0,379 puntos.
A19: e) Coeficiente de correlación: | B19: r = −0,686: correlación negativa moderada-fuerte entre ambas variables (r cercano a −0,7).
A20: f) Coeficiente de determinación: | B20: r² = 0,470: el 47% de la variabilidad del rendimiento académico se explica por las horas de uso de redes sociales; el 53% restante se debe a otros factores (hábitos de estudio, horas de sueño, etc.).
